{
 "cells": [
  {
   "cell_type": "code",
   "execution_count": 1,
   "metadata": {},
   "outputs": [
    {
     "data": {
      "text/html": [
       "<pre style=\"white-space:pre;overflow-x:auto;line-height:normal;font-family:Menlo,'DejaVu Sans Mono',consolas,'Courier New',monospace\"><span style=\"color: #7fbfbf; text-decoration-color: #7fbfbf\">[04/01/23 12:00:00] </span><span style=\"color: #000080; text-decoration-color: #000080\">INFO    </span> marvin.marvin: <span style=\"color: #000000; text-decoration-color: #000000; background-color: #ffffff\">Using OpenAI model </span><span style=\"color: #008000; text-decoration-color: #008000; background-color: #ffffff\">\"gpt-3.5-turbo\"</span>                        <a href=\"file:///Users/brianroepke/Projects/OpenAI/venv/lib/python3.11/site-packages/marvin/utilities/logging.py\" target=\"_blank\"><span style=\"color: #7f7f7f; text-decoration-color: #7f7f7f\">logging.py</span></a><span style=\"color: #7f7f7f; text-decoration-color: #7f7f7f\">:</span><a href=\"file:///Users/brianroepke/Projects/OpenAI/venv/lib/python3.11/site-packages/marvin/utilities/logging.py#50\" target=\"_blank\"><span style=\"color: #7f7f7f; text-decoration-color: #7f7f7f\">50</span></a>\n",
       "</pre>\n"
      ],
      "text/plain": [
       "\u001b[2;36m[04/01/23 12:00:00]\u001b[0m\u001b[2;36m \u001b[0m\u001b[34mINFO    \u001b[0m marvin.marvin: \u001b[39;49mUsing OpenAI model \u001b[0m\u001b[32;49m\"gpt-3.5-turbo\"\u001b[0m                        \u001b]8;id=163847;file:///Users/brianroepke/Projects/OpenAI/venv/lib/python3.11/site-packages/marvin/utilities/logging.py\u001b\\\u001b[2mlogging.py\u001b[0m\u001b]8;;\u001b\\\u001b[2m:\u001b[0m\u001b]8;id=285456;file:///Users/brianroepke/Projects/OpenAI/venv/lib/python3.11/site-packages/marvin/utilities/logging.py#50\u001b\\\u001b[2m50\u001b[0m\u001b]8;;\u001b\\\n"
      ]
     },
     "metadata": {},
     "output_type": "display_data"
    }
   ],
   "source": [
    "from marvin import ai_fn"
   ]
  },
  {
   "cell_type": "code",
   "execution_count": 2,
   "metadata": {},
   "outputs": [],
   "source": [
    "@ai_fn\n",
    "def list_of_primes(x):\n",
    "    \"\"\"Generate a list of x number of the first prime numbers\"\"\""
   ]
  },
  {
   "cell_type": "code",
   "execution_count": 3,
   "metadata": {},
   "outputs": [
    {
     "name": "stderr",
     "output_type": "stream",
     "text": [
      "Retrying langchain.chat_models.openai.acompletion_with_retry.<locals>._completion_with_retry in 4.0 seconds as it raised APIConnectionError: Error communicating with OpenAI.\n",
      "Retrying langchain.chat_models.openai.acompletion_with_retry.<locals>._completion_with_retry in 4.0 seconds as it raised APIConnectionError: Error communicating with OpenAI.\n",
      "Retrying langchain.chat_models.openai.acompletion_with_retry.<locals>._completion_with_retry in 4.0 seconds as it raised APIConnectionError: Error communicating with OpenAI.\n",
      "Retrying langchain.chat_models.openai.acompletion_with_retry.<locals>._completion_with_retry in 8.0 seconds as it raised APIConnectionError: Error communicating with OpenAI.\n",
      "Retrying langchain.chat_models.openai.acompletion_with_retry.<locals>._completion_with_retry in 10.0 seconds as it raised APIConnectionError: Error communicating with OpenAI.\n"
     ]
    },
    {
     "ename": "APIConnectionError",
     "evalue": "Error communicating with OpenAI",
     "output_type": "error",
     "traceback": [
      "\u001b[0;31m---------------------------------------------------------------------------\u001b[0m",
      "\u001b[0;31mSSLCertVerificationError\u001b[0m                  Traceback (most recent call last)",
      "File \u001b[0;32m~/Projects/OpenAI/venv/lib/python3.11/site-packages/aiohttp/connector.py:980\u001b[0m, in \u001b[0;36mTCPConnector._wrap_create_connection\u001b[0;34m(self, req, timeout, client_error, *args, **kwargs)\u001b[0m\n\u001b[1;32m    979\u001b[0m     \u001b[39masync\u001b[39;00m \u001b[39mwith\u001b[39;00m ceil_timeout(timeout\u001b[39m.\u001b[39msock_connect):\n\u001b[0;32m--> 980\u001b[0m         \u001b[39mreturn\u001b[39;00m \u001b[39mawait\u001b[39;00m \u001b[39mself\u001b[39m\u001b[39m.\u001b[39m_loop\u001b[39m.\u001b[39mcreate_connection(\u001b[39m*\u001b[39margs, \u001b[39m*\u001b[39m\u001b[39m*\u001b[39mkwargs)  \u001b[39m# type: ignore[return-value]  # noqa\u001b[39;00m\n\u001b[1;32m    981\u001b[0m \u001b[39mexcept\u001b[39;00m cert_errors \u001b[39mas\u001b[39;00m exc:\n",
      "File \u001b[0;32m/Library/Frameworks/Python.framework/Versions/3.11/lib/python3.11/asyncio/base_events.py:1106\u001b[0m, in \u001b[0;36mBaseEventLoop.create_connection\u001b[0;34m(self, protocol_factory, host, port, ssl, family, proto, flags, sock, local_addr, server_hostname, ssl_handshake_timeout, ssl_shutdown_timeout, happy_eyeballs_delay, interleave)\u001b[0m\n\u001b[1;32m   1103\u001b[0m         \u001b[39mraise\u001b[39;00m \u001b[39mValueError\u001b[39;00m(\n\u001b[1;32m   1104\u001b[0m             \u001b[39mf\u001b[39m\u001b[39m'\u001b[39m\u001b[39mA Stream Socket was expected, got \u001b[39m\u001b[39m{\u001b[39;00msock\u001b[39m!r}\u001b[39;00m\u001b[39m'\u001b[39m)\n\u001b[0;32m-> 1106\u001b[0m transport, protocol \u001b[39m=\u001b[39m \u001b[39mawait\u001b[39;00m \u001b[39mself\u001b[39m\u001b[39m.\u001b[39m_create_connection_transport(\n\u001b[1;32m   1107\u001b[0m     sock, protocol_factory, ssl, server_hostname,\n\u001b[1;32m   1108\u001b[0m     ssl_handshake_timeout\u001b[39m=\u001b[39mssl_handshake_timeout,\n\u001b[1;32m   1109\u001b[0m     ssl_shutdown_timeout\u001b[39m=\u001b[39mssl_shutdown_timeout)\n\u001b[1;32m   1110\u001b[0m \u001b[39mif\u001b[39;00m \u001b[39mself\u001b[39m\u001b[39m.\u001b[39m_debug:\n\u001b[1;32m   1111\u001b[0m     \u001b[39m# Get the socket from the transport because SSL transport closes\u001b[39;00m\n\u001b[1;32m   1112\u001b[0m     \u001b[39m# the old socket and creates a new SSL socket\u001b[39;00m\n",
      "File \u001b[0;32m/Library/Frameworks/Python.framework/Versions/3.11/lib/python3.11/asyncio/base_events.py:1139\u001b[0m, in \u001b[0;36mBaseEventLoop._create_connection_transport\u001b[0;34m(self, sock, protocol_factory, ssl, server_hostname, server_side, ssl_handshake_timeout, ssl_shutdown_timeout)\u001b[0m\n\u001b[1;32m   1138\u001b[0m \u001b[39mtry\u001b[39;00m:\n\u001b[0;32m-> 1139\u001b[0m     \u001b[39mawait\u001b[39;00m waiter\n\u001b[1;32m   1140\u001b[0m \u001b[39mexcept\u001b[39;00m:\n",
      "File \u001b[0;32m/Library/Frameworks/Python.framework/Versions/3.11/lib/python3.11/asyncio/futures.py:287\u001b[0m, in \u001b[0;36mFuture.__await__\u001b[0;34m(self)\u001b[0m\n\u001b[1;32m    286\u001b[0m     \u001b[39mself\u001b[39m\u001b[39m.\u001b[39m_asyncio_future_blocking \u001b[39m=\u001b[39m \u001b[39mTrue\u001b[39;00m\n\u001b[0;32m--> 287\u001b[0m     \u001b[39myield\u001b[39;00m \u001b[39mself\u001b[39m  \u001b[39m# This tells Task to wait for completion.\u001b[39;00m\n\u001b[1;32m    288\u001b[0m \u001b[39mif\u001b[39;00m \u001b[39mnot\u001b[39;00m \u001b[39mself\u001b[39m\u001b[39m.\u001b[39mdone():\n",
      "File \u001b[0;32m/Library/Frameworks/Python.framework/Versions/3.11/lib/python3.11/asyncio/tasks.py:339\u001b[0m, in \u001b[0;36mTask.__wakeup\u001b[0;34m(self, future)\u001b[0m\n\u001b[1;32m    338\u001b[0m \u001b[39mtry\u001b[39;00m:\n\u001b[0;32m--> 339\u001b[0m     future\u001b[39m.\u001b[39;49mresult()\n\u001b[1;32m    340\u001b[0m \u001b[39mexcept\u001b[39;00m \u001b[39mBaseException\u001b[39;00m \u001b[39mas\u001b[39;00m exc:\n\u001b[1;32m    341\u001b[0m     \u001b[39m# This may also be a cancellation.\u001b[39;00m\n",
      "File \u001b[0;32m/Library/Frameworks/Python.framework/Versions/3.11/lib/python3.11/asyncio/futures.py:203\u001b[0m, in \u001b[0;36mFuture.result\u001b[0;34m(self)\u001b[0m\n\u001b[1;32m    202\u001b[0m \u001b[39mif\u001b[39;00m \u001b[39mself\u001b[39m\u001b[39m.\u001b[39m_exception \u001b[39mis\u001b[39;00m \u001b[39mnot\u001b[39;00m \u001b[39mNone\u001b[39;00m:\n\u001b[0;32m--> 203\u001b[0m     \u001b[39mraise\u001b[39;00m \u001b[39mself\u001b[39m\u001b[39m.\u001b[39m_exception\u001b[39m.\u001b[39mwith_traceback(\u001b[39mself\u001b[39m\u001b[39m.\u001b[39m_exception_tb)\n\u001b[1;32m    204\u001b[0m \u001b[39mreturn\u001b[39;00m \u001b[39mself\u001b[39m\u001b[39m.\u001b[39m_result\n",
      "File \u001b[0;32m/Library/Frameworks/Python.framework/Versions/3.11/lib/python3.11/asyncio/sslproto.py:574\u001b[0m, in \u001b[0;36mSSLProtocol._on_handshake_complete\u001b[0;34m(self, handshake_exc)\u001b[0m\n\u001b[1;32m    573\u001b[0m \u001b[39melse\u001b[39;00m:\n\u001b[0;32m--> 574\u001b[0m     \u001b[39mraise\u001b[39;00m handshake_exc\n\u001b[1;32m    576\u001b[0m peercert \u001b[39m=\u001b[39m sslobj\u001b[39m.\u001b[39mgetpeercert()\n",
      "File \u001b[0;32m/Library/Frameworks/Python.framework/Versions/3.11/lib/python3.11/asyncio/sslproto.py:556\u001b[0m, in \u001b[0;36mSSLProtocol._do_handshake\u001b[0;34m(self)\u001b[0m\n\u001b[1;32m    555\u001b[0m \u001b[39mtry\u001b[39;00m:\n\u001b[0;32m--> 556\u001b[0m     \u001b[39mself\u001b[39;49m\u001b[39m.\u001b[39;49m_sslobj\u001b[39m.\u001b[39;49mdo_handshake()\n\u001b[1;32m    557\u001b[0m \u001b[39mexcept\u001b[39;00m SSLAgainErrors:\n",
      "File \u001b[0;32m/Library/Frameworks/Python.framework/Versions/3.11/lib/python3.11/ssl.py:979\u001b[0m, in \u001b[0;36mSSLObject.do_handshake\u001b[0;34m(self)\u001b[0m\n\u001b[1;32m    978\u001b[0m \u001b[39m\u001b[39m\u001b[39m\"\"\"Start the SSL/TLS handshake.\"\"\"\u001b[39;00m\n\u001b[0;32m--> 979\u001b[0m \u001b[39mself\u001b[39m\u001b[39m.\u001b[39m_sslobj\u001b[39m.\u001b[39mdo_handshake()\n",
      "\u001b[0;31mSSLCertVerificationError\u001b[0m: [SSL: CERTIFICATE_VERIFY_FAILED] certificate verify failed: unable to get local issuer certificate (_ssl.c:992)",
      "\nThe above exception was the direct cause of the following exception:\n",
      "\u001b[0;31mClientConnectorCertificateError\u001b[0m           Traceback (most recent call last)",
      "File \u001b[0;32m~/Projects/OpenAI/venv/lib/python3.11/site-packages/openai/api_requestor.py:587\u001b[0m, in \u001b[0;36mAPIRequestor.arequest_raw\u001b[0;34m(self, method, url, session, params, supplied_headers, files, request_id, request_timeout)\u001b[0m\n\u001b[1;32m    586\u001b[0m \u001b[39mtry\u001b[39;00m:\n\u001b[0;32m--> 587\u001b[0m     result \u001b[39m=\u001b[39m \u001b[39mawait\u001b[39;00m session\u001b[39m.\u001b[39mrequest(\u001b[39m*\u001b[39m\u001b[39m*\u001b[39mrequest_kwargs)\n\u001b[1;32m    588\u001b[0m     util\u001b[39m.\u001b[39mlog_info(\n\u001b[1;32m    589\u001b[0m         \u001b[39m\"\u001b[39m\u001b[39mOpenAI API response\u001b[39m\u001b[39m\"\u001b[39m,\n\u001b[1;32m    590\u001b[0m         path\u001b[39m=\u001b[39mabs_url,\n\u001b[0;32m   (...)\u001b[0m\n\u001b[1;32m    593\u001b[0m         request_id\u001b[39m=\u001b[39mresult\u001b[39m.\u001b[39mheaders\u001b[39m.\u001b[39mget(\u001b[39m\"\u001b[39m\u001b[39mX-Request-Id\u001b[39m\u001b[39m\"\u001b[39m),\n\u001b[1;32m    594\u001b[0m     )\n",
      "File \u001b[0;32m~/Projects/OpenAI/venv/lib/python3.11/site-packages/aiohttp/client.py:536\u001b[0m, in \u001b[0;36mClientSession._request\u001b[0;34m(self, method, str_or_url, params, data, json, cookies, headers, skip_auto_headers, auth, allow_redirects, max_redirects, compress, chunked, expect100, raise_for_status, read_until_eof, proxy, proxy_auth, timeout, verify_ssl, fingerprint, ssl_context, ssl, proxy_headers, trace_request_ctx, read_bufsize)\u001b[0m\n\u001b[1;32m    535\u001b[0m         \u001b[39massert\u001b[39;00m \u001b[39mself\u001b[39m\u001b[39m.\u001b[39m_connector \u001b[39mis\u001b[39;00m \u001b[39mnot\u001b[39;00m \u001b[39mNone\u001b[39;00m\n\u001b[0;32m--> 536\u001b[0m         conn \u001b[39m=\u001b[39m \u001b[39mawait\u001b[39;00m \u001b[39mself\u001b[39m\u001b[39m.\u001b[39m_connector\u001b[39m.\u001b[39mconnect(\n\u001b[1;32m    537\u001b[0m             req, traces\u001b[39m=\u001b[39mtraces, timeout\u001b[39m=\u001b[39mreal_timeout\n\u001b[1;32m    538\u001b[0m         )\n\u001b[1;32m    539\u001b[0m \u001b[39mexcept\u001b[39;00m asyncio\u001b[39m.\u001b[39mTimeoutError \u001b[39mas\u001b[39;00m exc:\n",
      "File \u001b[0;32m~/Projects/OpenAI/venv/lib/python3.11/site-packages/aiohttp/connector.py:540\u001b[0m, in \u001b[0;36mBaseConnector.connect\u001b[0;34m(self, req, traces, timeout)\u001b[0m\n\u001b[1;32m    539\u001b[0m \u001b[39mtry\u001b[39;00m:\n\u001b[0;32m--> 540\u001b[0m     proto \u001b[39m=\u001b[39m \u001b[39mawait\u001b[39;00m \u001b[39mself\u001b[39m\u001b[39m.\u001b[39m_create_connection(req, traces, timeout)\n\u001b[1;32m    541\u001b[0m     \u001b[39mif\u001b[39;00m \u001b[39mself\u001b[39m\u001b[39m.\u001b[39m_closed:\n",
      "File \u001b[0;32m~/Projects/OpenAI/venv/lib/python3.11/site-packages/aiohttp/connector.py:901\u001b[0m, in \u001b[0;36mTCPConnector._create_connection\u001b[0;34m(self, req, traces, timeout)\u001b[0m\n\u001b[1;32m    900\u001b[0m \u001b[39melse\u001b[39;00m:\n\u001b[0;32m--> 901\u001b[0m     _, proto \u001b[39m=\u001b[39m \u001b[39mawait\u001b[39;00m \u001b[39mself\u001b[39m\u001b[39m.\u001b[39m_create_direct_connection(req, traces, timeout)\n\u001b[1;32m    903\u001b[0m \u001b[39mreturn\u001b[39;00m proto\n",
      "File \u001b[0;32m~/Projects/OpenAI/venv/lib/python3.11/site-packages/aiohttp/connector.py:1206\u001b[0m, in \u001b[0;36mTCPConnector._create_direct_connection\u001b[0;34m(self, req, traces, timeout, client_error)\u001b[0m\n\u001b[1;32m   1205\u001b[0m \u001b[39massert\u001b[39;00m last_exc \u001b[39mis\u001b[39;00m \u001b[39mnot\u001b[39;00m \u001b[39mNone\u001b[39;00m\n\u001b[0;32m-> 1206\u001b[0m \u001b[39mraise\u001b[39;00m last_exc\n",
      "File \u001b[0;32m~/Projects/OpenAI/venv/lib/python3.11/site-packages/aiohttp/connector.py:1175\u001b[0m, in \u001b[0;36mTCPConnector._create_direct_connection\u001b[0;34m(self, req, traces, timeout, client_error)\u001b[0m\n\u001b[1;32m   1174\u001b[0m \u001b[39mtry\u001b[39;00m:\n\u001b[0;32m-> 1175\u001b[0m     transp, proto \u001b[39m=\u001b[39m \u001b[39mawait\u001b[39;00m \u001b[39mself\u001b[39m\u001b[39m.\u001b[39m_wrap_create_connection(\n\u001b[1;32m   1176\u001b[0m         \u001b[39mself\u001b[39m\u001b[39m.\u001b[39m_factory,\n\u001b[1;32m   1177\u001b[0m         host,\n\u001b[1;32m   1178\u001b[0m         port,\n\u001b[1;32m   1179\u001b[0m         timeout\u001b[39m=\u001b[39mtimeout,\n\u001b[1;32m   1180\u001b[0m         ssl\u001b[39m=\u001b[39msslcontext,\n\u001b[1;32m   1181\u001b[0m         family\u001b[39m=\u001b[39mhinfo[\u001b[39m\"\u001b[39m\u001b[39mfamily\u001b[39m\u001b[39m\"\u001b[39m],\n\u001b[1;32m   1182\u001b[0m         proto\u001b[39m=\u001b[39mhinfo[\u001b[39m\"\u001b[39m\u001b[39mproto\u001b[39m\u001b[39m\"\u001b[39m],\n\u001b[1;32m   1183\u001b[0m         flags\u001b[39m=\u001b[39mhinfo[\u001b[39m\"\u001b[39m\u001b[39mflags\u001b[39m\u001b[39m\"\u001b[39m],\n\u001b[1;32m   1184\u001b[0m         server_hostname\u001b[39m=\u001b[39mhinfo[\u001b[39m\"\u001b[39m\u001b[39mhostname\u001b[39m\u001b[39m\"\u001b[39m] \u001b[39mif\u001b[39;00m sslcontext \u001b[39melse\u001b[39;00m \u001b[39mNone\u001b[39;00m,\n\u001b[1;32m   1185\u001b[0m         local_addr\u001b[39m=\u001b[39m\u001b[39mself\u001b[39m\u001b[39m.\u001b[39m_local_addr,\n\u001b[1;32m   1186\u001b[0m         req\u001b[39m=\u001b[39mreq,\n\u001b[1;32m   1187\u001b[0m         client_error\u001b[39m=\u001b[39mclient_error,\n\u001b[1;32m   1188\u001b[0m     )\n\u001b[1;32m   1189\u001b[0m \u001b[39mexcept\u001b[39;00m ClientConnectorError \u001b[39mas\u001b[39;00m exc:\n",
      "File \u001b[0;32m~/Projects/OpenAI/venv/lib/python3.11/site-packages/aiohttp/connector.py:982\u001b[0m, in \u001b[0;36mTCPConnector._wrap_create_connection\u001b[0;34m(self, req, timeout, client_error, *args, **kwargs)\u001b[0m\n\u001b[1;32m    981\u001b[0m \u001b[39mexcept\u001b[39;00m cert_errors \u001b[39mas\u001b[39;00m exc:\n\u001b[0;32m--> 982\u001b[0m     \u001b[39mraise\u001b[39;00m ClientConnectorCertificateError(req\u001b[39m.\u001b[39mconnection_key, exc) \u001b[39mfrom\u001b[39;00m \u001b[39mexc\u001b[39;00m\n\u001b[1;32m    983\u001b[0m \u001b[39mexcept\u001b[39;00m ssl_errors \u001b[39mas\u001b[39;00m exc:\n",
      "\u001b[0;31mClientConnectorCertificateError\u001b[0m: Cannot connect to host api.openai.com:443 ssl:True [SSLCertVerificationError: (1, '[SSL: CERTIFICATE_VERIFY_FAILED] certificate verify failed: unable to get local issuer certificate (_ssl.c:992)')]",
      "\nThe above exception was the direct cause of the following exception:\n",
      "\u001b[0;31mAPIConnectionError\u001b[0m                        Traceback (most recent call last)",
      "Cell \u001b[0;32mIn[3], line 1\u001b[0m\n\u001b[0;32m----> 1\u001b[0m list_of_primes(\u001b[39m10\u001b[39;49m)\n",
      "File \u001b[0;32m~/Projects/OpenAI/venv/lib/python3.11/site-packages/marvin/bots/ai_functions.py:182\u001b[0m, in \u001b[0;36mai_fn.<locals>.ai_fn_wrapper\u001b[0;34m(*args, **kwargs)\u001b[0m\n\u001b[1;32m    180\u001b[0m     \u001b[39mreturn\u001b[39;00m get_response()\n\u001b[1;32m    181\u001b[0m \u001b[39melse\u001b[39;00m:\n\u001b[0;32m--> 182\u001b[0m     \u001b[39mreturn\u001b[39;00m asyncio\u001b[39m.\u001b[39;49mrun(get_response())\n",
      "File \u001b[0;32m~/Projects/OpenAI/venv/lib/python3.11/site-packages/nest_asyncio.py:35\u001b[0m, in \u001b[0;36m_patch_asyncio.<locals>.run\u001b[0;34m(main, debug)\u001b[0m\n\u001b[1;32m     33\u001b[0m task \u001b[39m=\u001b[39m asyncio\u001b[39m.\u001b[39mensure_future(main)\n\u001b[1;32m     34\u001b[0m \u001b[39mtry\u001b[39;00m:\n\u001b[0;32m---> 35\u001b[0m     \u001b[39mreturn\u001b[39;00m loop\u001b[39m.\u001b[39;49mrun_until_complete(task)\n\u001b[1;32m     36\u001b[0m \u001b[39mfinally\u001b[39;00m:\n\u001b[1;32m     37\u001b[0m     \u001b[39mif\u001b[39;00m \u001b[39mnot\u001b[39;00m task\u001b[39m.\u001b[39mdone():\n",
      "File \u001b[0;32m~/Projects/OpenAI/venv/lib/python3.11/site-packages/nest_asyncio.py:90\u001b[0m, in \u001b[0;36m_patch_loop.<locals>.run_until_complete\u001b[0;34m(self, future)\u001b[0m\n\u001b[1;32m     87\u001b[0m \u001b[39mif\u001b[39;00m \u001b[39mnot\u001b[39;00m f\u001b[39m.\u001b[39mdone():\n\u001b[1;32m     88\u001b[0m     \u001b[39mraise\u001b[39;00m \u001b[39mRuntimeError\u001b[39;00m(\n\u001b[1;32m     89\u001b[0m         \u001b[39m'\u001b[39m\u001b[39mEvent loop stopped before Future completed.\u001b[39m\u001b[39m'\u001b[39m)\n\u001b[0;32m---> 90\u001b[0m \u001b[39mreturn\u001b[39;00m f\u001b[39m.\u001b[39;49mresult()\n",
      "File \u001b[0;32m/Library/Frameworks/Python.framework/Versions/3.11/lib/python3.11/asyncio/futures.py:203\u001b[0m, in \u001b[0;36mFuture.result\u001b[0;34m(self)\u001b[0m\n\u001b[1;32m    201\u001b[0m \u001b[39mself\u001b[39m\u001b[39m.\u001b[39m__log_traceback \u001b[39m=\u001b[39m \u001b[39mFalse\u001b[39;00m\n\u001b[1;32m    202\u001b[0m \u001b[39mif\u001b[39;00m \u001b[39mself\u001b[39m\u001b[39m.\u001b[39m_exception \u001b[39mis\u001b[39;00m \u001b[39mnot\u001b[39;00m \u001b[39mNone\u001b[39;00m:\n\u001b[0;32m--> 203\u001b[0m     \u001b[39mraise\u001b[39;00m \u001b[39mself\u001b[39m\u001b[39m.\u001b[39m_exception\u001b[39m.\u001b[39mwith_traceback(\u001b[39mself\u001b[39m\u001b[39m.\u001b[39m_exception_tb)\n\u001b[1;32m    204\u001b[0m \u001b[39mreturn\u001b[39;00m \u001b[39mself\u001b[39m\u001b[39m.\u001b[39m_result\n",
      "File \u001b[0;32m/Library/Frameworks/Python.framework/Versions/3.11/lib/python3.11/asyncio/tasks.py:269\u001b[0m, in \u001b[0;36mTask.__step\u001b[0;34m(***failed resolving arguments***)\u001b[0m\n\u001b[1;32m    267\u001b[0m         result \u001b[39m=\u001b[39m coro\u001b[39m.\u001b[39msend(\u001b[39mNone\u001b[39;00m)\n\u001b[1;32m    268\u001b[0m     \u001b[39melse\u001b[39;00m:\n\u001b[0;32m--> 269\u001b[0m         result \u001b[39m=\u001b[39m coro\u001b[39m.\u001b[39mthrow(exc)\n\u001b[1;32m    270\u001b[0m \u001b[39mexcept\u001b[39;00m \u001b[39mStopIteration\u001b[39;00m \u001b[39mas\u001b[39;00m exc:\n\u001b[1;32m    271\u001b[0m     \u001b[39mif\u001b[39;00m \u001b[39mself\u001b[39m\u001b[39m.\u001b[39m_must_cancel:\n\u001b[1;32m    272\u001b[0m         \u001b[39m# Task is cancelled right before coro stops.\u001b[39;00m\n",
      "File \u001b[0;32m~/Projects/OpenAI/venv/lib/python3.11/site-packages/marvin/bots/ai_functions.py:176\u001b[0m, in \u001b[0;36mai_fn.<locals>.ai_fn_wrapper.<locals>.get_response\u001b[0;34m()\u001b[0m\n\u001b[1;32m    175\u001b[0m \u001b[39masync\u001b[39;00m \u001b[39mdef\u001b[39;00m \u001b[39mget_response\u001b[39m():\n\u001b[0;32m--> 176\u001b[0m     response \u001b[39m=\u001b[39m \u001b[39mawait\u001b[39;00m bot\u001b[39m.\u001b[39msay(message)\n\u001b[1;32m    177\u001b[0m     \u001b[39mreturn\u001b[39;00m response\u001b[39m.\u001b[39mparsed_content\n",
      "File \u001b[0;32m~/Projects/OpenAI/venv/lib/python3.11/site-packages/marvin/bots/base.py:281\u001b[0m, in \u001b[0;36mBot.say\u001b[0;34m(self, response_format, *args, **kwargs)\u001b[0m\n\u001b[1;32m    279\u001b[0m \u001b[39melse\u001b[39;00m:\n\u001b[1;32m    280\u001b[0m     counter \u001b[39m+\u001b[39m\u001b[39m=\u001b[39m \u001b[39m1\u001b[39m\n\u001b[0;32m--> 281\u001b[0m     response \u001b[39m=\u001b[39m \u001b[39mawait\u001b[39;00m \u001b[39mself\u001b[39m\u001b[39m.\u001b[39m_call_llm(messages\u001b[39m=\u001b[39mmessages)\n\u001b[1;32m    282\u001b[0m \u001b[39mif\u001b[39;00m \u001b[39mnot\u001b[39;00m finished:\n\u001b[1;32m    283\u001b[0m     plugin_messages \u001b[39m=\u001b[39m \u001b[39mawait\u001b[39;00m \u001b[39mself\u001b[39m\u001b[39m.\u001b[39m_check_for_plugins(response\u001b[39m=\u001b[39mresponse)\n",
      "File \u001b[0;32m~/Projects/OpenAI/venv/lib/python3.11/site-packages/marvin/bots/base.py:495\u001b[0m, in \u001b[0;36mBot._call_llm\u001b[0;34m(self, messages)\u001b[0m\n\u001b[1;32m    493\u001b[0m     \u001b[39mself\u001b[39m\u001b[39m.\u001b[39mlogger\u001b[39m.\u001b[39mdebug(\u001b[39mf\u001b[39m\u001b[39m\"\u001b[39m\u001b[39mSending messages to LLM: \u001b[39m\u001b[39m{\u001b[39;00mmessages_repr\u001b[39m}\u001b[39;00m\u001b[39m\"\u001b[39m)\n\u001b[1;32m    494\u001b[0m \u001b[39mtry\u001b[39;00m:\n\u001b[0;32m--> 495\u001b[0m     result \u001b[39m=\u001b[39m \u001b[39mawait\u001b[39;00m \u001b[39mself\u001b[39m\u001b[39m.\u001b[39mllm\u001b[39m.\u001b[39magenerate(\n\u001b[1;32m    496\u001b[0m         messages\u001b[39m=\u001b[39m[langchain_messages], stop\u001b[39m=\u001b[39m[\u001b[39m\"\u001b[39m\u001b[39mPlugin output:\u001b[39m\u001b[39m\"\u001b[39m, \u001b[39m\"\u001b[39m\u001b[39mPlugin Output:\u001b[39m\u001b[39m\"\u001b[39m]\n\u001b[1;32m    497\u001b[0m     )\n\u001b[1;32m    498\u001b[0m \u001b[39mexcept\u001b[39;00m InvalidRequestError \u001b[39mas\u001b[39;00m exc:\n\u001b[1;32m    499\u001b[0m     \u001b[39mif\u001b[39;00m \u001b[39m\"\u001b[39m\u001b[39mdoes not exist\u001b[39m\u001b[39m\"\u001b[39m \u001b[39min\u001b[39;00m \u001b[39mstr\u001b[39m(exc):\n",
      "File \u001b[0;32m~/Projects/OpenAI/venv/lib/python3.11/site-packages/langchain/chat_models/base.py:63\u001b[0m, in \u001b[0;36mBaseChatModel.agenerate\u001b[0;34m(self, messages, stop)\u001b[0m\n\u001b[1;32m     59\u001b[0m \u001b[39masync\u001b[39;00m \u001b[39mdef\u001b[39;00m \u001b[39magenerate\u001b[39m(\n\u001b[1;32m     60\u001b[0m     \u001b[39mself\u001b[39m, messages: List[List[BaseMessage]], stop: Optional[List[\u001b[39mstr\u001b[39m]] \u001b[39m=\u001b[39m \u001b[39mNone\u001b[39;00m\n\u001b[1;32m     61\u001b[0m ) \u001b[39m-\u001b[39m\u001b[39m>\u001b[39m LLMResult:\n\u001b[1;32m     62\u001b[0m \u001b[39m    \u001b[39m\u001b[39m\"\"\"Top Level call\"\"\"\u001b[39;00m\n\u001b[0;32m---> 63\u001b[0m     results \u001b[39m=\u001b[39m \u001b[39mawait\u001b[39;00m asyncio\u001b[39m.\u001b[39mgather(\n\u001b[1;32m     64\u001b[0m         \u001b[39m*\u001b[39m[\u001b[39mself\u001b[39m\u001b[39m.\u001b[39m_agenerate(m, stop\u001b[39m=\u001b[39mstop) \u001b[39mfor\u001b[39;00m m \u001b[39min\u001b[39;00m messages]\n\u001b[1;32m     65\u001b[0m     )\n\u001b[1;32m     66\u001b[0m     llm_output \u001b[39m=\u001b[39m \u001b[39mself\u001b[39m\u001b[39m.\u001b[39m_combine_llm_outputs([res\u001b[39m.\u001b[39mllm_output \u001b[39mfor\u001b[39;00m res \u001b[39min\u001b[39;00m results])\n\u001b[1;32m     67\u001b[0m     generations \u001b[39m=\u001b[39m [res\u001b[39m.\u001b[39mgenerations \u001b[39mfor\u001b[39;00m res \u001b[39min\u001b[39;00m results]\n",
      "File \u001b[0;32m/Library/Frameworks/Python.framework/Versions/3.11/lib/python3.11/asyncio/tasks.py:339\u001b[0m, in \u001b[0;36mTask.__wakeup\u001b[0;34m(self, future)\u001b[0m\n\u001b[1;32m    337\u001b[0m \u001b[39mdef\u001b[39;00m \u001b[39m__wakeup\u001b[39m(\u001b[39mself\u001b[39m, future):\n\u001b[1;32m    338\u001b[0m     \u001b[39mtry\u001b[39;00m:\n\u001b[0;32m--> 339\u001b[0m         future\u001b[39m.\u001b[39;49mresult()\n\u001b[1;32m    340\u001b[0m     \u001b[39mexcept\u001b[39;00m \u001b[39mBaseException\u001b[39;00m \u001b[39mas\u001b[39;00m exc:\n\u001b[1;32m    341\u001b[0m         \u001b[39m# This may also be a cancellation.\u001b[39;00m\n\u001b[1;32m    342\u001b[0m         \u001b[39mself\u001b[39m\u001b[39m.\u001b[39m__step(exc)\n",
      "File \u001b[0;32m/Library/Frameworks/Python.framework/Versions/3.11/lib/python3.11/asyncio/tasks.py:267\u001b[0m, in \u001b[0;36mTask.__step\u001b[0;34m(***failed resolving arguments***)\u001b[0m\n\u001b[1;32m    263\u001b[0m \u001b[39mtry\u001b[39;00m:\n\u001b[1;32m    264\u001b[0m     \u001b[39mif\u001b[39;00m exc \u001b[39mis\u001b[39;00m \u001b[39mNone\u001b[39;00m:\n\u001b[1;32m    265\u001b[0m         \u001b[39m# We use the `send` method directly, because coroutines\u001b[39;00m\n\u001b[1;32m    266\u001b[0m         \u001b[39m# don't have `__iter__` and `__next__` methods.\u001b[39;00m\n\u001b[0;32m--> 267\u001b[0m         result \u001b[39m=\u001b[39m coro\u001b[39m.\u001b[39msend(\u001b[39mNone\u001b[39;00m)\n\u001b[1;32m    268\u001b[0m     \u001b[39melse\u001b[39;00m:\n\u001b[1;32m    269\u001b[0m         result \u001b[39m=\u001b[39m coro\u001b[39m.\u001b[39mthrow(exc)\n",
      "File \u001b[0;32m~/Projects/OpenAI/venv/lib/python3.11/site-packages/langchain/chat_models/openai.py:308\u001b[0m, in \u001b[0;36mChatOpenAI._agenerate\u001b[0;34m(self, messages, stop)\u001b[0m\n\u001b[1;32m    306\u001b[0m     \u001b[39mreturn\u001b[39;00m ChatResult(generations\u001b[39m=\u001b[39m[ChatGeneration(message\u001b[39m=\u001b[39mmessage)])\n\u001b[1;32m    307\u001b[0m \u001b[39melse\u001b[39;00m:\n\u001b[0;32m--> 308\u001b[0m     response \u001b[39m=\u001b[39m \u001b[39mawait\u001b[39;00m acompletion_with_retry(\n\u001b[1;32m    309\u001b[0m         \u001b[39mself\u001b[39m, messages\u001b[39m=\u001b[39mmessage_dicts, \u001b[39m*\u001b[39m\u001b[39m*\u001b[39mparams\n\u001b[1;32m    310\u001b[0m     )\n\u001b[1;32m    311\u001b[0m     \u001b[39mreturn\u001b[39;00m \u001b[39mself\u001b[39m\u001b[39m.\u001b[39m_create_chat_result(response)\n",
      "File \u001b[0;32m~/Projects/OpenAI/venv/lib/python3.11/site-packages/langchain/chat_models/openai.py:63\u001b[0m, in \u001b[0;36macompletion_with_retry\u001b[0;34m(llm, **kwargs)\u001b[0m\n\u001b[1;32m     58\u001b[0m \u001b[39m@retry_decorator\u001b[39m\n\u001b[1;32m     59\u001b[0m \u001b[39masync\u001b[39;00m \u001b[39mdef\u001b[39;00m \u001b[39m_completion_with_retry\u001b[39m(\u001b[39m*\u001b[39m\u001b[39m*\u001b[39mkwargs: Any) \u001b[39m-\u001b[39m\u001b[39m>\u001b[39m Any:\n\u001b[1;32m     60\u001b[0m     \u001b[39m# Use OpenAI's async api https://github.com/openai/openai-python#async-api\u001b[39;00m\n\u001b[1;32m     61\u001b[0m     \u001b[39mreturn\u001b[39;00m \u001b[39mawait\u001b[39;00m llm\u001b[39m.\u001b[39mclient\u001b[39m.\u001b[39macreate(\u001b[39m*\u001b[39m\u001b[39m*\u001b[39mkwargs)\n\u001b[0;32m---> 63\u001b[0m \u001b[39mreturn\u001b[39;00m \u001b[39mawait\u001b[39;00m _completion_with_retry(\u001b[39m*\u001b[39m\u001b[39m*\u001b[39mkwargs)\n",
      "File \u001b[0;32m~/Projects/OpenAI/venv/lib/python3.11/site-packages/tenacity/_asyncio.py:88\u001b[0m, in \u001b[0;36mAsyncRetrying.wraps.<locals>.async_wrapped\u001b[0;34m(*args, **kwargs)\u001b[0m\n\u001b[1;32m     86\u001b[0m \u001b[39m@functools\u001b[39m\u001b[39m.\u001b[39mwraps(fn)\n\u001b[1;32m     87\u001b[0m \u001b[39masync\u001b[39;00m \u001b[39mdef\u001b[39;00m \u001b[39masync_wrapped\u001b[39m(\u001b[39m*\u001b[39margs: t\u001b[39m.\u001b[39mAny, \u001b[39m*\u001b[39m\u001b[39m*\u001b[39mkwargs: t\u001b[39m.\u001b[39mAny) \u001b[39m-\u001b[39m\u001b[39m>\u001b[39m t\u001b[39m.\u001b[39mAny:\n\u001b[0;32m---> 88\u001b[0m     \u001b[39mreturn\u001b[39;00m \u001b[39mawait\u001b[39;00m fn(\u001b[39m*\u001b[39margs, \u001b[39m*\u001b[39m\u001b[39m*\u001b[39mkwargs)\n",
      "File \u001b[0;32m~/Projects/OpenAI/venv/lib/python3.11/site-packages/tenacity/_asyncio.py:47\u001b[0m, in \u001b[0;36mAsyncRetrying.__call__\u001b[0;34m(self, fn, *args, **kwargs)\u001b[0m\n\u001b[1;32m     45\u001b[0m retry_state \u001b[39m=\u001b[39m RetryCallState(retry_object\u001b[39m=\u001b[39m\u001b[39mself\u001b[39m, fn\u001b[39m=\u001b[39mfn, args\u001b[39m=\u001b[39margs, kwargs\u001b[39m=\u001b[39mkwargs)\n\u001b[1;32m     46\u001b[0m \u001b[39mwhile\u001b[39;00m \u001b[39mTrue\u001b[39;00m:\n\u001b[0;32m---> 47\u001b[0m     do \u001b[39m=\u001b[39m \u001b[39mself\u001b[39;49m\u001b[39m.\u001b[39;49miter(retry_state\u001b[39m=\u001b[39;49mretry_state)\n\u001b[1;32m     48\u001b[0m     \u001b[39mif\u001b[39;00m \u001b[39misinstance\u001b[39m(do, DoAttempt):\n\u001b[1;32m     49\u001b[0m         \u001b[39mtry\u001b[39;00m:\n",
      "File \u001b[0;32m~/Projects/OpenAI/venv/lib/python3.11/site-packages/tenacity/__init__.py:325\u001b[0m, in \u001b[0;36mBaseRetrying.iter\u001b[0;34m(self, retry_state)\u001b[0m\n\u001b[1;32m    323\u001b[0m     retry_exc \u001b[39m=\u001b[39m \u001b[39mself\u001b[39m\u001b[39m.\u001b[39mretry_error_cls(fut)\n\u001b[1;32m    324\u001b[0m     \u001b[39mif\u001b[39;00m \u001b[39mself\u001b[39m\u001b[39m.\u001b[39mreraise:\n\u001b[0;32m--> 325\u001b[0m         \u001b[39mraise\u001b[39;00m retry_exc\u001b[39m.\u001b[39;49mreraise()\n\u001b[1;32m    326\u001b[0m     \u001b[39mraise\u001b[39;00m retry_exc \u001b[39mfrom\u001b[39;00m \u001b[39mfut\u001b[39;00m\u001b[39m.\u001b[39;00m\u001b[39mexception\u001b[39;00m()\n\u001b[1;32m    328\u001b[0m \u001b[39mif\u001b[39;00m \u001b[39mself\u001b[39m\u001b[39m.\u001b[39mwait:\n",
      "File \u001b[0;32m~/Projects/OpenAI/venv/lib/python3.11/site-packages/tenacity/__init__.py:158\u001b[0m, in \u001b[0;36mRetryError.reraise\u001b[0;34m(self)\u001b[0m\n\u001b[1;32m    156\u001b[0m \u001b[39mdef\u001b[39;00m \u001b[39mreraise\u001b[39m(\u001b[39mself\u001b[39m) \u001b[39m-\u001b[39m\u001b[39m>\u001b[39m t\u001b[39m.\u001b[39mNoReturn:\n\u001b[1;32m    157\u001b[0m     \u001b[39mif\u001b[39;00m \u001b[39mself\u001b[39m\u001b[39m.\u001b[39mlast_attempt\u001b[39m.\u001b[39mfailed:\n\u001b[0;32m--> 158\u001b[0m         \u001b[39mraise\u001b[39;00m \u001b[39mself\u001b[39;49m\u001b[39m.\u001b[39;49mlast_attempt\u001b[39m.\u001b[39;49mresult()\n\u001b[1;32m    159\u001b[0m     \u001b[39mraise\u001b[39;00m \u001b[39mself\u001b[39m\n",
      "File \u001b[0;32m/Library/Frameworks/Python.framework/Versions/3.11/lib/python3.11/concurrent/futures/_base.py:449\u001b[0m, in \u001b[0;36mFuture.result\u001b[0;34m(self, timeout)\u001b[0m\n\u001b[1;32m    447\u001b[0m     \u001b[39mraise\u001b[39;00m CancelledError()\n\u001b[1;32m    448\u001b[0m \u001b[39melif\u001b[39;00m \u001b[39mself\u001b[39m\u001b[39m.\u001b[39m_state \u001b[39m==\u001b[39m FINISHED:\n\u001b[0;32m--> 449\u001b[0m     \u001b[39mreturn\u001b[39;00m \u001b[39mself\u001b[39;49m\u001b[39m.\u001b[39;49m__get_result()\n\u001b[1;32m    451\u001b[0m \u001b[39mself\u001b[39m\u001b[39m.\u001b[39m_condition\u001b[39m.\u001b[39mwait(timeout)\n\u001b[1;32m    453\u001b[0m \u001b[39mif\u001b[39;00m \u001b[39mself\u001b[39m\u001b[39m.\u001b[39m_state \u001b[39min\u001b[39;00m [CANCELLED, CANCELLED_AND_NOTIFIED]:\n",
      "File \u001b[0;32m/Library/Frameworks/Python.framework/Versions/3.11/lib/python3.11/concurrent/futures/_base.py:401\u001b[0m, in \u001b[0;36mFuture.__get_result\u001b[0;34m(self)\u001b[0m\n\u001b[1;32m    399\u001b[0m \u001b[39mif\u001b[39;00m \u001b[39mself\u001b[39m\u001b[39m.\u001b[39m_exception:\n\u001b[1;32m    400\u001b[0m     \u001b[39mtry\u001b[39;00m:\n\u001b[0;32m--> 401\u001b[0m         \u001b[39mraise\u001b[39;00m \u001b[39mself\u001b[39m\u001b[39m.\u001b[39m_exception\n\u001b[1;32m    402\u001b[0m     \u001b[39mfinally\u001b[39;00m:\n\u001b[1;32m    403\u001b[0m         \u001b[39m# Break a reference cycle with the exception in self._exception\u001b[39;00m\n\u001b[1;32m    404\u001b[0m         \u001b[39mself\u001b[39m \u001b[39m=\u001b[39m \u001b[39mNone\u001b[39;00m\n",
      "File \u001b[0;32m~/Projects/OpenAI/venv/lib/python3.11/site-packages/tenacity/_asyncio.py:50\u001b[0m, in \u001b[0;36mAsyncRetrying.__call__\u001b[0;34m(self, fn, *args, **kwargs)\u001b[0m\n\u001b[1;32m     48\u001b[0m \u001b[39mif\u001b[39;00m \u001b[39misinstance\u001b[39m(do, DoAttempt):\n\u001b[1;32m     49\u001b[0m     \u001b[39mtry\u001b[39;00m:\n\u001b[0;32m---> 50\u001b[0m         result \u001b[39m=\u001b[39m \u001b[39mawait\u001b[39;00m fn(\u001b[39m*\u001b[39margs, \u001b[39m*\u001b[39m\u001b[39m*\u001b[39mkwargs)\n\u001b[1;32m     51\u001b[0m     \u001b[39mexcept\u001b[39;00m \u001b[39mBaseException\u001b[39;00m:  \u001b[39m# noqa: B902\u001b[39;00m\n\u001b[1;32m     52\u001b[0m         retry_state\u001b[39m.\u001b[39mset_exception(sys\u001b[39m.\u001b[39mexc_info())  \u001b[39m# type: ignore[arg-type]\u001b[39;00m\n",
      "File \u001b[0;32m~/Projects/OpenAI/venv/lib/python3.11/site-packages/langchain/chat_models/openai.py:61\u001b[0m, in \u001b[0;36macompletion_with_retry.<locals>._completion_with_retry\u001b[0;34m(**kwargs)\u001b[0m\n\u001b[1;32m     58\u001b[0m \u001b[39m@retry_decorator\u001b[39m\n\u001b[1;32m     59\u001b[0m \u001b[39masync\u001b[39;00m \u001b[39mdef\u001b[39;00m \u001b[39m_completion_with_retry\u001b[39m(\u001b[39m*\u001b[39m\u001b[39m*\u001b[39mkwargs: Any) \u001b[39m-\u001b[39m\u001b[39m>\u001b[39m Any:\n\u001b[1;32m     60\u001b[0m     \u001b[39m# Use OpenAI's async api https://github.com/openai/openai-python#async-api\u001b[39;00m\n\u001b[0;32m---> 61\u001b[0m     \u001b[39mreturn\u001b[39;00m \u001b[39mawait\u001b[39;00m llm\u001b[39m.\u001b[39mclient\u001b[39m.\u001b[39macreate(\u001b[39m*\u001b[39m\u001b[39m*\u001b[39mkwargs)\n",
      "File \u001b[0;32m~/Projects/OpenAI/venv/lib/python3.11/site-packages/openai/api_resources/chat_completion.py:45\u001b[0m, in \u001b[0;36mChatCompletion.acreate\u001b[0;34m(cls, *args, **kwargs)\u001b[0m\n\u001b[1;32m     43\u001b[0m \u001b[39mwhile\u001b[39;00m \u001b[39mTrue\u001b[39;00m:\n\u001b[1;32m     44\u001b[0m     \u001b[39mtry\u001b[39;00m:\n\u001b[0;32m---> 45\u001b[0m         \u001b[39mreturn\u001b[39;00m \u001b[39mawait\u001b[39;00m \u001b[39msuper\u001b[39m()\u001b[39m.\u001b[39macreate(\u001b[39m*\u001b[39margs, \u001b[39m*\u001b[39m\u001b[39m*\u001b[39mkwargs)\n\u001b[1;32m     46\u001b[0m     \u001b[39mexcept\u001b[39;00m TryAgain \u001b[39mas\u001b[39;00m e:\n\u001b[1;32m     47\u001b[0m         \u001b[39mif\u001b[39;00m timeout \u001b[39mis\u001b[39;00m \u001b[39mnot\u001b[39;00m \u001b[39mNone\u001b[39;00m \u001b[39mand\u001b[39;00m time\u001b[39m.\u001b[39mtime() \u001b[39m>\u001b[39m start \u001b[39m+\u001b[39m timeout:\n",
      "File \u001b[0;32m~/Projects/OpenAI/venv/lib/python3.11/site-packages/openai/api_resources/abstract/engine_api_resource.py:217\u001b[0m, in \u001b[0;36mEngineAPIResource.acreate\u001b[0;34m(cls, api_key, api_base, api_type, request_id, api_version, organization, **params)\u001b[0m\n\u001b[1;32m    192\u001b[0m \u001b[39m@classmethod\u001b[39m\n\u001b[1;32m    193\u001b[0m \u001b[39masync\u001b[39;00m \u001b[39mdef\u001b[39;00m \u001b[39macreate\u001b[39m(\n\u001b[1;32m    194\u001b[0m     \u001b[39mcls\u001b[39m,\n\u001b[0;32m   (...)\u001b[0m\n\u001b[1;32m    201\u001b[0m     \u001b[39m*\u001b[39m\u001b[39m*\u001b[39mparams,\n\u001b[1;32m    202\u001b[0m ):\n\u001b[1;32m    203\u001b[0m     (\n\u001b[1;32m    204\u001b[0m         deployment_id,\n\u001b[1;32m    205\u001b[0m         engine,\n\u001b[0;32m   (...)\u001b[0m\n\u001b[1;32m    215\u001b[0m         api_key, api_base, api_type, api_version, organization, \u001b[39m*\u001b[39m\u001b[39m*\u001b[39mparams\n\u001b[1;32m    216\u001b[0m     )\n\u001b[0;32m--> 217\u001b[0m     response, _, api_key \u001b[39m=\u001b[39m \u001b[39mawait\u001b[39;00m requestor\u001b[39m.\u001b[39marequest(\n\u001b[1;32m    218\u001b[0m         \u001b[39m\"\u001b[39m\u001b[39mpost\u001b[39m\u001b[39m\"\u001b[39m,\n\u001b[1;32m    219\u001b[0m         url,\n\u001b[1;32m    220\u001b[0m         params\u001b[39m=\u001b[39mparams,\n\u001b[1;32m    221\u001b[0m         headers\u001b[39m=\u001b[39mheaders,\n\u001b[1;32m    222\u001b[0m         stream\u001b[39m=\u001b[39mstream,\n\u001b[1;32m    223\u001b[0m         request_id\u001b[39m=\u001b[39mrequest_id,\n\u001b[1;32m    224\u001b[0m         request_timeout\u001b[39m=\u001b[39mrequest_timeout,\n\u001b[1;32m    225\u001b[0m     )\n\u001b[1;32m    227\u001b[0m     \u001b[39mif\u001b[39;00m stream:\n\u001b[1;32m    228\u001b[0m         \u001b[39m# must be an iterator\u001b[39;00m\n\u001b[1;32m    229\u001b[0m         \u001b[39massert\u001b[39;00m \u001b[39mnot\u001b[39;00m \u001b[39misinstance\u001b[39m(response, OpenAIResponse)\n",
      "File \u001b[0;32m~/Projects/OpenAI/venv/lib/python3.11/site-packages/openai/api_requestor.py:300\u001b[0m, in \u001b[0;36mAPIRequestor.arequest\u001b[0;34m(self, method, url, params, headers, files, stream, request_id, request_timeout)\u001b[0m\n\u001b[1;32m    298\u001b[0m session \u001b[39m=\u001b[39m \u001b[39mawait\u001b[39;00m ctx\u001b[39m.\u001b[39m\u001b[39m__aenter__\u001b[39m()\n\u001b[1;32m    299\u001b[0m \u001b[39mtry\u001b[39;00m:\n\u001b[0;32m--> 300\u001b[0m     result \u001b[39m=\u001b[39m \u001b[39mawait\u001b[39;00m \u001b[39mself\u001b[39m\u001b[39m.\u001b[39marequest_raw(\n\u001b[1;32m    301\u001b[0m         method\u001b[39m.\u001b[39mlower(),\n\u001b[1;32m    302\u001b[0m         url,\n\u001b[1;32m    303\u001b[0m         session,\n\u001b[1;32m    304\u001b[0m         params\u001b[39m=\u001b[39mparams,\n\u001b[1;32m    305\u001b[0m         supplied_headers\u001b[39m=\u001b[39mheaders,\n\u001b[1;32m    306\u001b[0m         files\u001b[39m=\u001b[39mfiles,\n\u001b[1;32m    307\u001b[0m         request_id\u001b[39m=\u001b[39mrequest_id,\n\u001b[1;32m    308\u001b[0m         request_timeout\u001b[39m=\u001b[39mrequest_timeout,\n\u001b[1;32m    309\u001b[0m     )\n\u001b[1;32m    310\u001b[0m     resp, got_stream \u001b[39m=\u001b[39m \u001b[39mawait\u001b[39;00m \u001b[39mself\u001b[39m\u001b[39m.\u001b[39m_interpret_async_response(result, stream)\n\u001b[1;32m    311\u001b[0m \u001b[39mexcept\u001b[39;00m \u001b[39mException\u001b[39;00m:\n",
      "File \u001b[0;32m~/Projects/OpenAI/venv/lib/python3.11/site-packages/openai/api_requestor.py:604\u001b[0m, in \u001b[0;36mAPIRequestor.arequest_raw\u001b[0;34m(self, method, url, session, params, supplied_headers, files, request_id, request_timeout)\u001b[0m\n\u001b[1;32m    602\u001b[0m     \u001b[39mraise\u001b[39;00m error\u001b[39m.\u001b[39mTimeout(\u001b[39m\"\u001b[39m\u001b[39mRequest timed out\u001b[39m\u001b[39m\"\u001b[39m) \u001b[39mfrom\u001b[39;00m \u001b[39me\u001b[39;00m\n\u001b[1;32m    603\u001b[0m \u001b[39mexcept\u001b[39;00m aiohttp\u001b[39m.\u001b[39mClientError \u001b[39mas\u001b[39;00m e:\n\u001b[0;32m--> 604\u001b[0m     \u001b[39mraise\u001b[39;00m error\u001b[39m.\u001b[39mAPIConnectionError(\u001b[39m\"\u001b[39m\u001b[39mError communicating with OpenAI\u001b[39m\u001b[39m\"\u001b[39m) \u001b[39mfrom\u001b[39;00m \u001b[39me\u001b[39;00m\n",
      "\u001b[0;31mAPIConnectionError\u001b[0m: Error communicating with OpenAI"
     ]
    }
   ],
   "source": [
    "list_of_primes(10)"
   ]
  },
  {
   "cell_type": "code",
   "execution_count": null,
   "metadata": {},
   "outputs": [],
   "source": []
  }
 ],
 "metadata": {
  "kernelspec": {
   "display_name": "venv",
   "language": "python",
   "name": "python3"
  },
  "language_info": {
   "codemirror_mode": {
    "name": "ipython",
    "version": 3
   },
   "file_extension": ".py",
   "mimetype": "text/x-python",
   "name": "python",
   "nbconvert_exporter": "python",
   "pygments_lexer": "ipython3",
   "version": "3.11.1"
  },
  "orig_nbformat": 4,
  "vscode": {
   "interpreter": {
    "hash": "9f486034883a202e8bea762f9972b42d879f888bc5f2dc5507c770b39c0383c7"
   }
  }
 },
 "nbformat": 4,
 "nbformat_minor": 2
}
